[2025-08-18T15:28:59.229+0000] {taskinstance.py:1103} INFO - Dependencies all met for dep_context=non-requeueable deps ti=<TaskInstance: validate_sensor_data.run_sensor_validation scheduled__2025-08-18T15:24:00+00:00 [queued]>
[2025-08-18T15:28:59.251+0000] {taskinstance.py:1103} INFO - Dependencies all met for dep_context=requeueable deps ti=<TaskInstance: validate_sensor_data.run_sensor_validation scheduled__2025-08-18T15:24:00+00:00 [queued]>
[2025-08-18T15:28:59.252+0000] {taskinstance.py:1308} INFO - Starting attempt 1 of 1
[2025-08-18T15:28:59.277+0000] {taskinstance.py:1327} INFO - Executing <Task(PythonOperator): run_sensor_validation> on 2025-08-18 15:24:00+00:00
[2025-08-18T15:28:59.299+0000] {standard_task_runner.py:57} INFO - Started process 422 to run task
[2025-08-18T15:28:59.305+0000] {standard_task_runner.py:84} INFO - Running: ['airflow', 'tasks', 'run', 'validate_sensor_data', 'run_sensor_validation', 'scheduled__2025-08-18T15:24:00+00:00', '--job-id', '451', '--raw', '--subdir', 'DAGS_FOLDER/validate_sensor_data_dag.py', '--cfg-path', '/tmp/tmp91d8_v76']
[2025-08-18T15:28:59.306+0000] {standard_task_runner.py:85} INFO - Job 451: Subtask run_sensor_validation
[2025-08-18T15:28:59.393+0000] {task_command.py:410} INFO - Running <TaskInstance: validate_sensor_data.run_sensor_validation scheduled__2025-08-18T15:24:00+00:00 [running]> on host 82ba84950a6e
[2025-08-18T15:28:59.627+0000] {taskinstance.py:1547} INFO - Exporting env vars: AIRFLOW_CTX_DAG_OWNER='airflow' AIRFLOW_CTX_DAG_ID='validate_sensor_data' AIRFLOW_CTX_TASK_ID='run_sensor_validation' AIRFLOW_CTX_EXECUTION_DATE='2025-08-18T15:24:00+00:00' AIRFLOW_CTX_TRY_NUMBER='1' AIRFLOW_CTX_DAG_RUN_ID='scheduled__2025-08-18T15:24:00+00:00'
[2025-08-18T15:28:59.876+0000] {util.py:1938} INFO - Could not find local context root directory
[2025-08-18T15:28:59.878+0000] {abstract_data_context.py:5421} INFO - EphemeralDataContext has not implemented `_load_zep_config()` returning empty `GxConfig`
[2025-08-18T15:28:59.878+0000] {config.py:53} INFO - Loading 'datasources' ->
{}
[2025-08-18T15:28:59.879+0000] {config.py:79} INFO - Loaded 'datasources' ->
{}
[2025-08-18T15:28:59.928+0000] {warnings.py:110} WARNING - /home/airflow/.local/lib/python3.7/site-packages/great_expectations/data_context/data_context/abstract_data_context.py:2708: DeprecationWarning: create_expectation_suite is deprecated as of v0.15.48 and will be removed in v0.18. Please use add_expectation_suite or add_or_update_expectation_suite instead.
  DeprecationWarning,

[2025-08-18T15:28:59.939+0000] {taskinstance.py:1824} ERROR - Task failed with exception
Traceback (most recent call last):
  File "/home/airflow/.local/lib/python3.7/site-packages/airflow/operators/python.py", line 181, in execute
    return_value = self.execute_callable()
  File "/home/airflow/.local/lib/python3.7/site-packages/airflow/operators/python.py", line 198, in execute_callable
    return self.python_callable(*self.op_args, **self.op_kwargs)
  File "/opt/airflow/dags/data_validation/sensor_validator.py", line 33, in validate_sensor_data
    expectation_suite_name=suite_name,
  File "/home/airflow/.local/lib/python3.7/site-packages/great_expectations/data_context/data_context/abstract_data_context.py", line 2430, in get_validator
    **kwargs,
  File "/home/airflow/.local/lib/python3.7/site-packages/great_expectations/core/usage_statistics/usage_statistics.py", line 318, in usage_statistics_wrapped_method
    result = func(*args, **kwargs)
  File "/home/airflow/.local/lib/python3.7/site-packages/great_expectations/data_context/data_context/abstract_data_context.py", line 2597, in get_batch_list
    **kwargs,
  File "/home/airflow/.local/lib/python3.7/site-packages/great_expectations/data_context/data_context/abstract_data_context.py", line 2651, in _get_batch_list
    "The given datasource could not be retrieved from the DataContext; "
great_expectations.exceptions.exceptions.DatasourceError: Cannot initialize datasource pandas_datasource, error: The given datasource could not be retrieved from the DataContext; please confirm that your configuration is accurate.
[2025-08-18T15:28:59.964+0000] {taskinstance.py:1350} INFO - Marking task as FAILED. dag_id=validate_sensor_data, task_id=run_sensor_validation, execution_date=20250818T152400, start_date=20250818T152859, end_date=20250818T152859
[2025-08-18T15:28:59.992+0000] {standard_task_runner.py:109} ERROR - Failed to execute job 451 for task run_sensor_validation (Cannot initialize datasource pandas_datasource, error: The given datasource could not be retrieved from the DataContext; please confirm that your configuration is accurate.; 422)
[2025-08-18T15:29:00.043+0000] {local_task_job_runner.py:225} INFO - Task exited with return code 1
[2025-08-18T15:29:00.078+0000] {taskinstance.py:2651} INFO - 0 downstream tasks scheduled from follow-on schedule check
