[2025-08-16T19:35:34.408+0000] {taskinstance.py:1103} INFO - Dependencies all met for dep_context=non-requeueable deps ti=<TaskInstance: nitro_data_pipeline.process_with_spark manual__2025-08-16T19:35:30.934419+00:00 [queued]>
[2025-08-16T19:35:34.421+0000] {taskinstance.py:1103} INFO - Dependencies all met for dep_context=requeueable deps ti=<TaskInstance: nitro_data_pipeline.process_with_spark manual__2025-08-16T19:35:30.934419+00:00 [queued]>
[2025-08-16T19:35:34.421+0000] {taskinstance.py:1308} INFO - Starting attempt 1 of 1
[2025-08-16T19:35:34.439+0000] {taskinstance.py:1327} INFO - Executing <Task(PythonOperator): process_with_spark> on 2025-08-16 19:35:30.934419+00:00
[2025-08-16T19:35:34.446+0000] {standard_task_runner.py:57} INFO - Started process 685 to run task
[2025-08-16T19:35:34.452+0000] {standard_task_runner.py:84} INFO - Running: ['airflow', 'tasks', 'run', 'nitro_data_pipeline', 'process_with_spark', 'manual__2025-08-16T19:35:30.934419+00:00', '--job-id', '2', '--raw', '--subdir', 'DAGS_FOLDER/data_pipeline.py', '--cfg-path', '/tmp/tmpswzyklx1']
[2025-08-16T19:35:34.455+0000] {standard_task_runner.py:85} INFO - Job 2: Subtask process_with_spark
[2025-08-16T19:35:34.569+0000] {task_command.py:410} INFO - Running <TaskInstance: nitro_data_pipeline.process_with_spark manual__2025-08-16T19:35:30.934419+00:00 [running]> on host cf481ce9be37
[2025-08-16T19:35:34.759+0000] {taskinstance.py:1547} INFO - Exporting env vars: AIRFLOW_CTX_DAG_OWNER='airflow' AIRFLOW_CTX_DAG_ID='nitro_data_pipeline' AIRFLOW_CTX_TASK_ID='process_with_spark' AIRFLOW_CTX_EXECUTION_DATE='2025-08-16T19:35:30.934419+00:00' AIRFLOW_CTX_TRY_NUMBER='1' AIRFLOW_CTX_DAG_RUN_ID='manual__2025-08-16T19:35:30.934419+00:00'
[2025-08-16T19:35:45.686+0000] {taskinstance.py:1824} ERROR - Task failed with exception
Traceback (most recent call last):
  File "/home/airflow/.local/lib/python3.7/site-packages/airflow/operators/python.py", line 181, in execute
    return_value = self.execute_callable()
  File "/home/airflow/.local/lib/python3.7/site-packages/airflow/operators/python.py", line 198, in execute_callable
    return self.python_callable(*self.op_args, **self.op_kwargs)
  File "/opt/airflow/dags/data_pipeline.py", line 10, in process_with_spark
    .config("spark.jars.packages", "org.postgresql:postgresql:42.5.0") \
  File "/home/airflow/.local/lib/python3.7/site-packages/pyspark/sql/session.py", line 269, in getOrCreate
    sc = SparkContext.getOrCreate(sparkConf)
  File "/home/airflow/.local/lib/python3.7/site-packages/pyspark/context.py", line 483, in getOrCreate
    SparkContext(conf=conf or SparkConf())
  File "/home/airflow/.local/lib/python3.7/site-packages/pyspark/context.py", line 195, in __init__
    SparkContext._ensure_initialized(self, gateway=gateway, conf=conf)
  File "/home/airflow/.local/lib/python3.7/site-packages/pyspark/context.py", line 417, in _ensure_initialized
    SparkContext._gateway = gateway or launch_gateway(conf)
  File "/home/airflow/.local/lib/python3.7/site-packages/pyspark/java_gateway.py", line 106, in launch_gateway
    raise RuntimeError("Java gateway process exited before sending its port number")
RuntimeError: Java gateway process exited before sending its port number
[2025-08-16T19:35:45.720+0000] {taskinstance.py:1350} INFO - Marking task as FAILED. dag_id=nitro_data_pipeline, task_id=process_with_spark, execution_date=20250816T193530, start_date=20250816T193534, end_date=20250816T193545
[2025-08-16T19:35:45.765+0000] {standard_task_runner.py:109} ERROR - Failed to execute job 2 for task process_with_spark (Java gateway process exited before sending its port number; 685)
[2025-08-16T19:35:45.827+0000] {local_task_job_runner.py:225} INFO - Task exited with return code 1
[2025-08-16T19:35:45.881+0000] {taskinstance.py:2651} INFO - 0 downstream tasks scheduled from follow-on schedule check
