[2025-08-18T12:41:11.653+0000] {taskinstance.py:1103} INFO - Dependencies all met for dep_context=non-requeueable deps ti=<TaskInstance: nitro_data_pipeline.process_with_spark manual__2025-08-18T12:41:01+00:00 [queued]>
[2025-08-18T12:41:11.756+0000] {taskinstance.py:1103} INFO - Dependencies all met for dep_context=requeueable deps ti=<TaskInstance: nitro_data_pipeline.process_with_spark manual__2025-08-18T12:41:01+00:00 [queued]>
[2025-08-18T12:41:11.759+0000] {taskinstance.py:1308} INFO - Starting attempt 1 of 1
[2025-08-18T12:41:12.139+0000] {taskinstance.py:1327} INFO - Executing <Task(PythonOperator): process_with_spark> on 2025-08-18 12:41:01+00:00
[2025-08-18T12:41:12.207+0000] {standard_task_runner.py:57} INFO - Started process 30157 to run task
[2025-08-18T12:41:12.251+0000] {standard_task_runner.py:84} INFO - Running: ['airflow', 'tasks', 'run', 'nitro_data_pipeline', 'process_with_spark', 'manual__2025-08-18T12:41:01+00:00', '--job-id', '360', '--raw', '--subdir', 'DAGS_FOLDER/data_pipeline.py', '--cfg-path', '/tmp/tmp34_kz2qu']
[2025-08-18T12:41:12.287+0000] {standard_task_runner.py:85} INFO - Job 360: Subtask process_with_spark
[2025-08-18T12:41:12.641+0000] {task_command.py:410} INFO - Running <TaskInstance: nitro_data_pipeline.process_with_spark manual__2025-08-18T12:41:01+00:00 [running]> on host e3730e5f69d2
[2025-08-18T12:41:13.871+0000] {taskinstance.py:1547} INFO - Exporting env vars: AIRFLOW_CTX_DAG_OWNER='airflow' AIRFLOW_CTX_DAG_ID='nitro_data_pipeline' AIRFLOW_CTX_TASK_ID='process_with_spark' AIRFLOW_CTX_EXECUTION_DATE='2025-08-18T12:41:01+00:00' AIRFLOW_CTX_TRY_NUMBER='1' AIRFLOW_CTX_DAG_RUN_ID='manual__2025-08-18T12:41:01+00:00'
[2025-08-18T12:41:13.879+0000] {logging_mixin.py:149} INFO - ===== INICIANDO PROCESO DE SPARK =====
[2025-08-18T12:42:16.129+0000] {logging_mixin.py:149} INFO - ===== LEYENDO JSON DESDE MINIO =====
[2025-08-18T12:45:50.677+0000] {local_task_job_runner.py:292} WARNING - State of this instance has been externally set to None. Terminating instance.
[2025-08-18T12:45:50.702+0000] {process_utils.py:135} INFO - Sending Signals.SIGTERM to group 30157. PIDs of all processes in the group: [30168, 30157]
[2025-08-18T12:45:50.703+0000] {process_utils.py:86} INFO - Sending the signal Signals.SIGTERM to group 30157
[2025-08-18T12:45:50.708+0000] {taskinstance.py:1517} ERROR - Received SIGTERM. Terminating subprocesses.
[2025-08-18T12:45:50.709+0000] {clientserver.py:538} INFO - Error while receiving.
Traceback (most recent call last):
  File "/home/airflow/.local/lib/python3.7/site-packages/py4j/clientserver.py", line 511, in send_command
    answer = smart_decode(self.stream.readline()[:-1])
  File "/usr/local/lib/python3.7/socket.py", line 589, in readinto
    return self._sock.recv_into(b)
  File "/home/airflow/.local/lib/python3.7/site-packages/airflow/models/taskinstance.py", line 1519, in signal_handler
    raise AirflowException("Task received SIGTERM signal")
airflow.exceptions.AirflowException: Task received SIGTERM signal
[2025-08-18T12:45:50.742+0000] {clientserver.py:543} INFO - Closing down clientserver connection
[2025-08-18T12:45:50.743+0000] {java_gateway.py:1056} ERROR - Exception while sending command.
Traceback (most recent call last):
  File "/home/airflow/.local/lib/python3.7/site-packages/py4j/clientserver.py", line 511, in send_command
    answer = smart_decode(self.stream.readline()[:-1])
  File "/usr/local/lib/python3.7/socket.py", line 589, in readinto
    return self._sock.recv_into(b)
  File "/home/airflow/.local/lib/python3.7/site-packages/airflow/models/taskinstance.py", line 1519, in signal_handler
    raise AirflowException("Task received SIGTERM signal")
airflow.exceptions.AirflowException: Task received SIGTERM signal

During handling of the above exception, another exception occurred:

Traceback (most recent call last):
  File "/home/airflow/.local/lib/python3.7/site-packages/py4j/java_gateway.py", line 1038, in send_command
    response = connection.send_command(command)
  File "/home/airflow/.local/lib/python3.7/site-packages/py4j/clientserver.py", line 540, in send_command
    "Error while sending or receiving", e, proto.ERROR_ON_RECEIVE)
py4j.protocol.Py4JNetworkError: Error while sending or receiving
[2025-08-18T12:45:50.749+0000] {clientserver.py:543} INFO - Closing down clientserver connection
[2025-08-18T12:45:50.750+0000] {taskinstance.py:1824} ERROR - Task failed with exception
Traceback (most recent call last):
  File "/home/airflow/.local/lib/python3.7/site-packages/airflow/operators/python.py", line 181, in execute
    return_value = self.execute_callable()
  File "/home/airflow/.local/lib/python3.7/site-packages/airflow/operators/python.py", line 198, in execute_callable
    return self.python_callable(*self.op_args, **self.op_kwargs)
  File "/opt/airflow/dags/data_pipeline.py", line 24, in process_with_spark
    df = spark.read.json("s3a://raw-data/*.json")
  File "/home/airflow/.local/lib/python3.7/site-packages/pyspark/sql/readwriter.py", line 284, in json
    return self._df(self._jreader.json(self._spark._sc._jvm.PythonUtils.toSeq(path)))
  File "/home/airflow/.local/lib/python3.7/site-packages/py4j/java_gateway.py", line 1322, in __call__
    answer, self.gateway_client, self.target_id, self.name)
  File "/home/airflow/.local/lib/python3.7/site-packages/pyspark/sql/utils.py", line 190, in deco
    return f(*a, **kw)
  File "/home/airflow/.local/lib/python3.7/site-packages/py4j/protocol.py", line 336, in get_return_value
    format(target_id, ".", name))
py4j.protocol.Py4JError: An error occurred while calling o31.json
[2025-08-18T12:45:50.812+0000] {taskinstance.py:1350} INFO - Marking task as FAILED. dag_id=nitro_data_pipeline, task_id=process_with_spark, execution_date=20250818T124101, start_date=20250818T124111, end_date=20250818T124550
[2025-08-18T12:45:50.860+0000] {standard_task_runner.py:109} ERROR - Failed to execute job 360 for task process_with_spark (An error occurred while calling o31.json; 30157)
[2025-08-18T12:45:51.221+0000] {process_utils.py:79} INFO - Process psutil.Process(pid=30157, status='terminated', exitcode=1, started='12:41:11') (30157) terminated with exit code 1
[2025-08-18T12:45:51.923+0000] {process_utils.py:79} INFO - Process psutil.Process(pid=30168, status='terminated', started='12:41:13') (30168) terminated with exit code None
