[2025-08-17T17:12:05.505+0000] {taskinstance.py:1103} INFO - Dependencies all met for dep_context=non-requeueable deps ti=<TaskInstance: validate_sensor_data.run_sensor_validation scheduled__2025-08-17T17:09:00+00:00 [queued]>
[2025-08-17T17:12:05.517+0000] {taskinstance.py:1103} INFO - Dependencies all met for dep_context=requeueable deps ti=<TaskInstance: validate_sensor_data.run_sensor_validation scheduled__2025-08-17T17:09:00+00:00 [queued]>
[2025-08-17T17:12:05.517+0000] {taskinstance.py:1308} INFO - Starting attempt 1 of 1
[2025-08-17T17:12:05.536+0000] {taskinstance.py:1327} INFO - Executing <Task(PythonOperator): run_sensor_validation> on 2025-08-17 17:09:00+00:00
[2025-08-17T17:12:05.545+0000] {standard_task_runner.py:57} INFO - Started process 25846 to run task
[2025-08-17T17:12:05.551+0000] {standard_task_runner.py:84} INFO - Running: ['airflow', 'tasks', 'run', 'validate_sensor_data', 'run_sensor_validation', 'scheduled__2025-08-17T17:09:00+00:00', '--job-id', '209', '--raw', '--subdir', 'DAGS_FOLDER/validate_sensor_data_dag.py', '--cfg-path', '/tmp/tmpanygcery']
[2025-08-17T17:12:05.551+0000] {standard_task_runner.py:85} INFO - Job 209: Subtask run_sensor_validation
[2025-08-17T17:12:05.634+0000] {task_command.py:410} INFO - Running <TaskInstance: validate_sensor_data.run_sensor_validation scheduled__2025-08-17T17:09:00+00:00 [running]> on host 4860d8807aa2
[2025-08-17T17:12:05.757+0000] {taskinstance.py:1547} INFO - Exporting env vars: AIRFLOW_CTX_DAG_OWNER='airflow' AIRFLOW_CTX_DAG_ID='validate_sensor_data' AIRFLOW_CTX_TASK_ID='run_sensor_validation' AIRFLOW_CTX_EXECUTION_DATE='2025-08-17T17:09:00+00:00' AIRFLOW_CTX_TRY_NUMBER='1' AIRFLOW_CTX_DAG_RUN_ID='scheduled__2025-08-17T17:09:00+00:00'
[2025-08-17T17:12:05.827+0000] {util.py:2007} INFO - Could not find local context root directory
[2025-08-17T17:12:05.830+0000] {abstract_data_context.py:5575} INFO - EphemeralDataContext has not implemented `_load_fluent_config()` returning empty `GxConfig`
[2025-08-17T17:12:05.831+0000] {config.py:185} INFO - Loading 'datasources' ->
[]
[2025-08-17T17:12:05.877+0000] {warnings.py:110} WARNING - /home/airflow/.local/lib/python3.7/site-packages/great_expectations/data_context/data_context/abstract_data_context.py:2846: DeprecationWarning: create_expectation_suite is deprecated as of v0.15.48 and will be removed in v0.18. Please use add_expectation_suite or add_or_update_expectation_suite instead.
  DeprecationWarning,

[2025-08-17T17:12:05.888+0000] {taskinstance.py:1824} ERROR - Task failed with exception
Traceback (most recent call last):
  File "/home/airflow/.local/lib/python3.7/site-packages/airflow/operators/python.py", line 181, in execute
    return_value = self.execute_callable()
  File "/home/airflow/.local/lib/python3.7/site-packages/airflow/operators/python.py", line 198, in execute_callable
    return self.python_callable(*self.op_args, **self.op_kwargs)
  File "/opt/airflow/dags/data_validation/sensor_validator.py", line 33, in validate_sensor_data
    expectation_suite_name=suite_name,
  File "/home/airflow/.local/lib/python3.7/site-packages/great_expectations/data_context/data_context/abstract_data_context.py", line 2561, in get_validator
    **kwargs,
  File "/home/airflow/.local/lib/python3.7/site-packages/great_expectations/core/usage_statistics/usage_statistics.py", line 318, in usage_statistics_wrapped_method
    result = func(*args, **kwargs)
  File "/home/airflow/.local/lib/python3.7/site-packages/great_expectations/data_context/data_context/abstract_data_context.py", line 2731, in get_batch_list
    **kwargs,
  File "/home/airflow/.local/lib/python3.7/site-packages/great_expectations/data_context/data_context/abstract_data_context.py", line 2785, in _get_batch_list
    "The given datasource could not be retrieved from the DataContext; "
great_expectations.exceptions.exceptions.DatasourceError: Cannot initialize datasource pandas_datasource, error: The given datasource could not be retrieved from the DataContext; please confirm that your configuration is accurate.
[2025-08-17T17:12:05.911+0000] {taskinstance.py:1350} INFO - Marking task as FAILED. dag_id=validate_sensor_data, task_id=run_sensor_validation, execution_date=20250817T170900, start_date=20250817T171205, end_date=20250817T171205
[2025-08-17T17:12:05.932+0000] {standard_task_runner.py:109} ERROR - Failed to execute job 209 for task run_sensor_validation (Cannot initialize datasource pandas_datasource, error: The given datasource could not be retrieved from the DataContext; please confirm that your configuration is accurate.; 25846)
[2025-08-17T17:12:05.964+0000] {local_task_job_runner.py:225} INFO - Task exited with return code 1
[2025-08-17T17:12:05.995+0000] {taskinstance.py:2651} INFO - 0 downstream tasks scheduled from follow-on schedule check
