[2025-08-18T13:21:21.789+0000] {taskinstance.py:1103} INFO - Dependencies all met for dep_context=non-requeueable deps ti=<TaskInstance: nitro_data_pipeline.process_with_spark scheduled__2025-08-18T13:18:00+00:00 [queued]>
[2025-08-18T13:21:21.828+0000] {taskinstance.py:1103} INFO - Dependencies all met for dep_context=requeueable deps ti=<TaskInstance: nitro_data_pipeline.process_with_spark scheduled__2025-08-18T13:18:00+00:00 [queued]>
[2025-08-18T13:21:21.829+0000] {taskinstance.py:1308} INFO - Starting attempt 1 of 1
[2025-08-18T13:21:21.956+0000] {taskinstance.py:1327} INFO - Executing <Task(PythonOperator): process_with_spark> on 2025-08-18 13:18:00+00:00
[2025-08-18T13:21:22.029+0000] {standard_task_runner.py:57} INFO - Started process 40252 to run task
[2025-08-18T13:21:22.142+0000] {standard_task_runner.py:84} INFO - Running: ['airflow', 'tasks', 'run', 'nitro_data_pipeline', 'process_with_spark', 'scheduled__2025-08-18T13:18:00+00:00', '--job-id', '391', '--raw', '--subdir', 'DAGS_FOLDER/data_pipeline.py', '--cfg-path', '/tmp/tmp_r5gr3ae']
[2025-08-18T13:21:22.281+0000] {standard_task_runner.py:85} INFO - Job 391: Subtask process_with_spark
[2025-08-18T13:21:22.875+0000] {task_command.py:410} INFO - Running <TaskInstance: nitro_data_pipeline.process_with_spark scheduled__2025-08-18T13:18:00+00:00 [running]> on host e3730e5f69d2
[2025-08-18T13:21:24.229+0000] {taskinstance.py:1547} INFO - Exporting env vars: AIRFLOW_CTX_DAG_OWNER='airflow' AIRFLOW_CTX_DAG_ID='nitro_data_pipeline' AIRFLOW_CTX_TASK_ID='process_with_spark' AIRFLOW_CTX_EXECUTION_DATE='2025-08-18T13:18:00+00:00' AIRFLOW_CTX_TRY_NUMBER='1' AIRFLOW_CTX_DAG_RUN_ID='scheduled__2025-08-18T13:18:00+00:00'
[2025-08-18T13:21:24.244+0000] {logging_mixin.py:149} INFO - ===== INICIANDO PROCESO DE SPARK =====
[2025-08-18T13:22:42.765+0000] {logging_mixin.py:149} INFO - ===== LEYENDO JSON DESDE MINIO =====
[2025-08-18T13:25:19.552+0000] {local_task_job_runner.py:292} WARNING - State of this instance has been externally set to queued. Terminating instance.
[2025-08-18T13:25:19.776+0000] {process_utils.py:135} INFO - Sending Signals.SIGTERM to group 40252. PIDs of all processes in the group: [40259, 40252]
[2025-08-18T13:25:19.944+0000] {process_utils.py:86} INFO - Sending the signal Signals.SIGTERM to group 40252
[2025-08-18T13:25:20.297+0000] {taskinstance.py:1517} ERROR - Received SIGTERM. Terminating subprocesses.
[2025-08-18T13:25:20.395+0000] {clientserver.py:538} INFO - Error while receiving.
Traceback (most recent call last):
  File "/home/airflow/.local/lib/python3.7/site-packages/py4j/clientserver.py", line 511, in send_command
    answer = smart_decode(self.stream.readline()[:-1])
  File "/usr/local/lib/python3.7/socket.py", line 589, in readinto
    return self._sock.recv_into(b)
  File "/home/airflow/.local/lib/python3.7/site-packages/airflow/models/taskinstance.py", line 1519, in signal_handler
    raise AirflowException("Task received SIGTERM signal")
airflow.exceptions.AirflowException: Task received SIGTERM signal
[2025-08-18T13:26:51.449+0000] {clientserver.py:543} INFO - Closing down clientserver connection
[2025-08-18T13:26:51.347+0000] {process_utils.py:149} WARNING - process psutil.Process(pid=40252, name='airflow task ru', status='sleeping', started='13:21:21') did not respond to SIGTERM. Trying SIGKILL
[2025-08-18T13:26:51.471+0000] {process_utils.py:149} WARNING - process psutil.Process(pid=40259, name='java', status='sleeping', started='13:21:23') did not respond to SIGTERM. Trying SIGKILL
[2025-08-18T13:26:51.474+0000] {process_utils.py:86} INFO - Sending the signal Signals.SIGKILL to group 40252
[2025-08-18T13:26:51.618+0000] {process_utils.py:79} INFO - Process psutil.Process(pid=40252, name='airflow task ru', status='terminated', exitcode=<Negsignal.SIGKILL: -9>, started='13:21:21') (40252) terminated with exit code Negsignal.SIGKILL
[2025-08-18T13:26:52.708+0000] {process_utils.py:79} INFO - Process psutil.Process(pid=40259, name='java', status='terminated', started='13:21:23') (40259) terminated with exit code None
[2025-08-18T13:26:52.714+0000] {standard_task_runner.py:174} ERROR - Job 391 was killed before it finished (likely due to running out of memory)
